[2022-08-23 13:06:00 +0000] [9] [INFO] Starting gunicorn 20.1.0
[2022-08-23 13:06:00 +0000] [9] [INFO] Listening at: http://0.0.0.0:5000 (9)
[2022-08-23 13:06:00 +0000] [9] [INFO] Using worker: sync
[2022-08-23 13:06:00 +0000] [12] [INFO] Booting worker with pid: 12
[2022-08-23 13:06:00 +0000] [14] [INFO] Booting worker with pid: 14
[2022-08-23 13:06:00 +0000] [15] [INFO] Booting worker with pid: 15
[2022-08-23 13:06:00 +0000] [17] [INFO] Booting worker with pid: 17
[2022-08-23 13:10:46 +0000] [9] [INFO] Handling signal: term
[2022-08-23 13:10:46 +0000] [9] [INFO] Shutting down: Master
[2022-08-23 13:11:25 +0000] [9] [INFO] Starting gunicorn 20.1.0
[2022-08-23 13:11:25 +0000] [9] [INFO] Listening at: http://0.0.0.0:5000 (9)
[2022-08-23 13:11:25 +0000] [9] [INFO] Using worker: sync
[2022-08-23 13:11:25 +0000] [12] [INFO] Booting worker with pid: 12
[2022-08-23 13:11:25 +0000] [13] [INFO] Booting worker with pid: 13
[2022-08-23 13:11:25 +0000] [15] [INFO] Booting worker with pid: 15
[2022-08-23 13:11:25 +0000] [18] [INFO] Booting worker with pid: 18
[2022-08-23 13:11:33 +0000] [9] [INFO] Handling signal: term
[2022-08-23 13:11:33 +0000] [9] [INFO] Shutting down: Master
[2022-08-23 13:12:12 +0000] [9] [INFO] Starting gunicorn 20.1.0
[2022-08-23 13:12:12 +0000] [9] [INFO] Listening at: http://0.0.0.0:5000 (9)
[2022-08-23 13:12:12 +0000] [9] [INFO] Using worker: sync
[2022-08-23 13:12:12 +0000] [12] [INFO] Booting worker with pid: 12
[2022-08-23 13:12:12 +0000] [13] [INFO] Booting worker with pid: 13
[2022-08-23 13:12:12 +0000] [15] [INFO] Booting worker with pid: 15
[2022-08-23 13:12:12 +0000] [16] [INFO] Booting worker with pid: 16
[2022-08-23 13:12:13 +0000] [12] [ERROR] Exception in worker process
Traceback (most recent call last):
  File "/usr/local/lib/python3.6/dist-packages/gunicorn/arbiter.py", line 589, in spawn_worker
    worker.init_process()
  File "/usr/local/lib/python3.6/dist-packages/gunicorn/workers/base.py", line 134, in init_process
    self.load_wsgi()
  File "/usr/local/lib/python3.6/dist-packages/gunicorn/workers/base.py", line 146, in load_wsgi
    self.wsgi = self.app.wsgi()
  File "/usr/local/lib/python3.6/dist-packages/gunicorn/app/base.py", line 67, in wsgi
    self.callable = self.load()
  File "/usr/local/lib/python3.6/dist-packages/gunicorn/app/wsgiapp.py", line 58, in load
    return self.load_wsgiapp()
  File "/usr/local/lib/python3.6/dist-packages/gunicorn/app/wsgiapp.py", line 48, in load_wsgiapp
    return util.import_app(self.app_uri)
  File "/usr/local/lib/python3.6/dist-packages/gunicorn/util.py", line 359, in import_app
    mod = importlib.import_module(module)
  File "/usr/lib/python3.6/importlib/__init__.py", line 126, in import_module
    return _bootstrap._gcd_import(name[level:], package, level)
  File "<frozen importlib._bootstrap>", line 994, in _gcd_import
  File "<frozen importlib._bootstrap>", line 971, in _find_and_load
  File "<frozen importlib._bootstrap>", line 955, in _find_and_load_unlocked
  File "<frozen importlib._bootstrap>", line 665, in _load_unlocked
  File "<frozen importlib._bootstrap_external>", line 678, in exec_module
  File "<frozen importlib._bootstrap>", line 219, in _call_with_frames_removed
  File "/home/dive/main.py", line 2, in <module>
    from diveapi import app
  File "/home/dive/diveapi/__init__.py", line 12, in <module>
    fileConfig('/app/config/logger.cfg')
  File "/usr/lib/python3.6/logging/config.py", line 84, in fileConfig
    handlers = _install_handlers(cp, formatters)
  File "/usr/lib/python3.6/logging/config.py", line 148, in _install_handlers
    h = klass(*args)
  File "/usr/lib/python3.6/logging/__init__.py", line 1032, in __init__
    StreamHandler.__init__(self, self._open())
  File "/usr/lib/python3.6/logging/__init__.py", line 1061, in _open
    return open(self.baseFilename, self.mode, encoding=self.encoding)
PermissionError: [Errno 13] Permission denied: '/app/logs/diveapi.log'
[2022-08-23 13:12:13 +0000] [12] [INFO] Worker exiting (pid: 12)
[2022-08-23 13:12:13 +0000] [13] [ERROR] Exception in worker process
Traceback (most recent call last):
  File "/usr/local/lib/python3.6/dist-packages/gunicorn/arbiter.py", line 589, in spawn_worker
    worker.init_process()
  File "/usr/local/lib/python3.6/dist-packages/gunicorn/workers/base.py", line 134, in init_process
    self.load_wsgi()
  File "/usr/local/lib/python3.6/dist-packages/gunicorn/workers/base.py", line 146, in load_wsgi
    self.wsgi = self.app.wsgi()
  File "/usr/local/lib/python3.6/dist-packages/gunicorn/app/base.py", line 67, in wsgi
    self.callable = self.load()
  File "/usr/local/lib/python3.6/dist-packages/gunicorn/app/wsgiapp.py", line 58, in load
    return self.load_wsgiapp()
  File "/usr/local/lib/python3.6/dist-packages/gunicorn/app/wsgiapp.py", line 48, in load_wsgiapp
    return util.import_app(self.app_uri)
  File "/usr/local/lib/python3.6/dist-packages/gunicorn/util.py", line 359, in import_app
    mod = importlib.import_module(module)
  File "/usr/lib/python3.6/importlib/__init__.py", line 126, in import_module
    return _bootstrap._gcd_import(name[level:], package, level)
  File "<frozen importlib._bootstrap>", line 994, in _gcd_import
  File "<frozen importlib._bootstrap>", line 971, in _find_and_load
  File "<frozen importlib._bootstrap>", line 955, in _find_and_load_unlocked
  File "<frozen importlib._bootstrap>", line 665, in _load_unlocked
  File "<frozen importlib._bootstrap_external>", line 678, in exec_module
  File "<frozen importlib._bootstrap>", line 219, in _call_with_frames_removed
  File "/home/dive/main.py", line 2, in <module>
    from diveapi import app
  File "/home/dive/diveapi/__init__.py", line 12, in <module>
    fileConfig('/app/config/logger.cfg')
  File "/usr/lib/python3.6/logging/config.py", line 84, in fileConfig
    handlers = _install_handlers(cp, formatters)
  File "/usr/lib/python3.6/logging/config.py", line 148, in _install_handlers
    h = klass(*args)
  File "/usr/lib/python3.6/logging/__init__.py", line 1032, in __init__
    StreamHandler.__init__(self, self._open())
  File "/usr/lib/python3.6/logging/__init__.py", line 1061, in _open
    return open(self.baseFilename, self.mode, encoding=self.encoding)
PermissionError: [Errno 13] Permission denied: '/app/logs/diveapi.log'
[2022-08-23 13:12:13 +0000] [13] [INFO] Worker exiting (pid: 13)
[2022-08-23 13:12:13 +0000] [15] [ERROR] Exception in worker process
Traceback (most recent call last):
  File "/usr/local/lib/python3.6/dist-packages/gunicorn/arbiter.py", line 589, in spawn_worker
    worker.init_process()
  File "/usr/local/lib/python3.6/dist-packages/gunicorn/workers/base.py", line 134, in init_process
    self.load_wsgi()
  File "/usr/local/lib/python3.6/dist-packages/gunicorn/workers/base.py", line 146, in load_wsgi
    self.wsgi = self.app.wsgi()
  File "/usr/local/lib/python3.6/dist-packages/gunicorn/app/base.py", line 67, in wsgi
    self.callable = self.load()
  File "/usr/local/lib/python3.6/dist-packages/gunicorn/app/wsgiapp.py", line 58, in load
    return self.load_wsgiapp()
  File "/usr/local/lib/python3.6/dist-packages/gunicorn/app/wsgiapp.py", line 48, in load_wsgiapp
    return util.import_app(self.app_uri)
  File "/usr/local/lib/python3.6/dist-packages/gunicorn/util.py", line 359, in import_app
    mod = importlib.import_module(module)
  File "/usr/lib/python3.6/importlib/__init__.py", line 126, in import_module
    return _bootstrap._gcd_import(name[level:], package, level)
  File "<frozen importlib._bootstrap>", line 994, in _gcd_import
  File "<frozen importlib._bootstrap>", line 971, in _find_and_load
  File "<frozen importlib._bootstrap>", line 955, in _find_and_load_unlocked
  File "<frozen importlib._bootstrap>", line 665, in _load_unlocked
  File "<frozen importlib._bootstrap_external>", line 678, in exec_module
  File "<frozen importlib._bootstrap>", line 219, in _call_with_frames_removed
  File "/home/dive/main.py", line 2, in <module>
    from diveapi import app
  File "/home/dive/diveapi/__init__.py", line 12, in <module>
    fileConfig('/app/config/logger.cfg')
  File "/usr/lib/python3.6/logging/config.py", line 84, in fileConfig
    handlers = _install_handlers(cp, formatters)
  File "/usr/lib/python3.6/logging/config.py", line 148, in _install_handlers
    h = klass(*args)
  File "/usr/lib/python3.6/logging/__init__.py", line 1032, in __init__
    StreamHandler.__init__(self, self._open())
  File "/usr/lib/python3.6/logging/__init__.py", line 1061, in _open
    return open(self.baseFilename, self.mode, encoding=self.encoding)
PermissionError: [Errno 13] Permission denied: '/app/logs/diveapi.log'
[2022-08-23 13:12:13 +0000] [15] [INFO] Worker exiting (pid: 15)
Traceback (most recent call last):
  File "/usr/local/lib/python3.6/dist-packages/gunicorn/arbiter.py", line 209, in run
    self.sleep()
  File "/usr/local/lib/python3.6/dist-packages/gunicorn/arbiter.py", line 357, in sleep
    ready = select.select([self.PIPE[0]], [], [], 1.0)
  File "/usr/local/lib/python3.6/dist-packages/gunicorn/arbiter.py", line 242, in handle_chld
    self.reap_workers()
  File "/usr/local/lib/python3.6/dist-packages/gunicorn/arbiter.py", line 525, in reap_workers
    raise HaltServer(reason, self.WORKER_BOOT_ERROR)
gunicorn.errors.HaltServer: <HaltServer 'Worker failed to boot.' 3>

During handling of the above exception, another exception occurred:

Traceback (most recent call last):
  File "/usr/local/bin/gunicorn", line 11, in <module>
    sys.exit(run())
  File "/usr/local/lib/python3.6/dist-packages/gunicorn/app/wsgiapp.py", line 67, in run
    WSGIApplication("%(prog)s [OPTIONS] [APP_MODULE]").run()
  File "/usr/local/lib/python3.6/dist-packages/gunicorn/app/base.py", line 231, in run
    super().run()
  File "/usr/local/lib/python3.6/dist-packages/gunicorn/app/base.py", line 72, in run
    Arbiter(self).run()
  File "/usr/local/lib/python3.6/dist-packages/gunicorn/arbiter.py", line 229, in run
    self.halt(reason=inst.reason, exit_status=inst.exit_status)
  File "/usr/local/lib/python3.6/dist-packages/gunicorn/arbiter.py", line 342, in halt
    self.stop()
  File "/usr/local/lib/python3.6/dist-packages/gunicorn/arbiter.py", line 393, in stop
    time.sleep(0.1)
  File "/usr/local/lib/python3.6/dist-packages/gunicorn/arbiter.py", line 242, in handle_chld
    self.reap_workers()
  File "/usr/local/lib/python3.6/dist-packages/gunicorn/arbiter.py", line 525, in reap_workers
    raise HaltServer(reason, self.WORKER_BOOT_ERROR)
gunicorn.errors.HaltServer: <HaltServer 'Worker failed to boot.' 3>
[2022-08-23 13:12:14 +0000] [20] [INFO] Starting gunicorn 20.1.0
[2022-08-23 13:12:14 +0000] [20] [INFO] Listening at: http://0.0.0.0:5000 (20)
[2022-08-23 13:12:14 +0000] [20] [INFO] Using worker: sync
[2022-08-23 13:12:14 +0000] [23] [INFO] Booting worker with pid: 23
[2022-08-23 13:12:14 +0000] [24] [INFO] Booting worker with pid: 24
[2022-08-23 13:12:14 +0000] [25] [INFO] Booting worker with pid: 25
[2022-08-23 13:12:14 +0000] [27] [INFO] Booting worker with pid: 27
[2022-08-23 13:12:14 +0000] [23] [ERROR] Exception in worker process
Traceback (most recent call last):
  File "/usr/local/lib/python3.6/dist-packages/gunicorn/arbiter.py", line 589, in spawn_worker
    worker.init_process()
  File "/usr/local/lib/python3.6/dist-packages/gunicorn/workers/base.py", line 134, in init_process
    self.load_wsgi()
  File "/usr/local/lib/python3.6/dist-packages/gunicorn/workers/base.py", line 146, in load_wsgi
    self.wsgi = self.app.wsgi()
  File "/usr/local/lib/python3.6/dist-packages/gunicorn/app/base.py", line 67, in wsgi
    self.callable = self.load()
  File "/usr/local/lib/python3.6/dist-packages/gunicorn/app/wsgiapp.py", line 58, in load
    return self.load_wsgiapp()
  File "/usr/local/lib/python3.6/dist-packages/gunicorn/app/wsgiapp.py", line 48, in load_wsgiapp
    return util.import_app(self.app_uri)
  File "/usr/local/lib/python3.6/dist-packages/gunicorn/util.py", line 359, in import_app
    mod = importlib.import_module(module)
  File "/usr/lib/python3.6/importlib/__init__.py", line 126, in import_module
    return _bootstrap._gcd_import(name[level:], package, level)
  File "<frozen importlib._bootstrap>", line 994, in _gcd_import
  File "<frozen importlib._bootstrap>", line 971, in _find_and_load
  File "<frozen importlib._bootstrap>", line 955, in _find_and_load_unlocked
  File "<frozen importlib._bootstrap>", line 665, in _load_unlocked
  File "<frozen importlib._bootstrap_external>", line 678, in exec_module
  File "<frozen importlib._bootstrap>", line 219, in _call_with_frames_removed
  File "/home/dive/main.py", line 2, in <module>
    from diveapi import app
  File "/home/dive/diveapi/__init__.py", line 12, in <module>
    fileConfig('/app/config/logger.cfg')
  File "/usr/lib/python3.6/logging/config.py", line 84, in fileConfig
    handlers = _install_handlers(cp, formatters)
  File "/usr/lib/python3.6/logging/config.py", line 148, in _install_handlers
    h = klass(*args)
  File "/usr/lib/python3.6/logging/__init__.py", line 1032, in __init__
    StreamHandler.__init__(self, self._open())
  File "/usr/lib/python3.6/logging/__init__.py", line 1061, in _open
    return open(self.baseFilename, self.mode, encoding=self.encoding)
PermissionError: [Errno 13] Permission denied: '/app/logs/diveapi.log'
[2022-08-23 13:12:14 +0000] [23] [INFO] Worker exiting (pid: 23)
[2022-08-23 13:12:14 +0000] [24] [ERROR] Exception in worker process
Traceback (most recent call last):
  File "/usr/local/lib/python3.6/dist-packages/gunicorn/arbiter.py", line 589, in spawn_worker
    worker.init_process()
  File "/usr/local/lib/python3.6/dist-packages/gunicorn/workers/base.py", line 134, in init_process
    self.load_wsgi()
  File "/usr/local/lib/python3.6/dist-packages/gunicorn/workers/base.py", line 146, in load_wsgi
    self.wsgi = self.app.wsgi()
  File "/usr/local/lib/python3.6/dist-packages/gunicorn/app/base.py", line 67, in wsgi
    self.callable = self.load()
  File "/usr/local/lib/python3.6/dist-packages/gunicorn/app/wsgiapp.py", line 58, in load
    return self.load_wsgiapp()
  File "/usr/local/lib/python3.6/dist-packages/gunicorn/app/wsgiapp.py", line 48, in load_wsgiapp
    return util.import_app(self.app_uri)
  File "/usr/local/lib/python3.6/dist-packages/gunicorn/util.py", line 359, in import_app
    mod = importlib.import_module(module)
  File "/usr/lib/python3.6/importlib/__init__.py", line 126, in import_module
    return _bootstrap._gcd_import(name[level:], package, level)
  File "<frozen importlib._bootstrap>", line 994, in _gcd_import
  File "<frozen importlib._bootstrap>", line 971, in _find_and_load
  File "<frozen importlib._bootstrap>", line 955, in _find_and_load_unlocked
  File "<frozen importlib._bootstrap>", line 665, in _load_unlocked
  File "<frozen importlib._bootstrap_external>", line 678, in exec_module
  File "<frozen importlib._bootstrap>", line 219, in _call_with_frames_removed
  File "/home/dive/main.py", line 2, in <module>
    from diveapi import app
  File "/home/dive/diveapi/__init__.py", line 12, in <module>
    fileConfig('/app/config/logger.cfg')
  File "/usr/lib/python3.6/logging/config.py", line 84, in fileConfig
    handlers = _install_handlers(cp, formatters)
  File "/usr/lib/python3.6/logging/config.py", line 148, in _install_handlers
    h = klass(*args)
  File "/usr/lib/python3.6/logging/__init__.py", line 1032, in __init__
    StreamHandler.__init__(self, self._open())
  File "/usr/lib/python3.6/logging/__init__.py", line 1061, in _open
    return open(self.baseFilename, self.mode, encoding=self.encoding)
PermissionError: [Errno 13] Permission denied: '/app/logs/diveapi.log'
[2022-08-23 13:12:14 +0000] [24] [INFO] Worker exiting (pid: 24)
[2022-08-23 13:12:14 +0000] [25] [ERROR] Exception in worker process
Traceback (most recent call last):
  File "/usr/local/lib/python3.6/dist-packages/gunicorn/arbiter.py", line 589, in spawn_worker
    worker.init_process()
  File "/usr/local/lib/python3.6/dist-packages/gunicorn/workers/base.py", line 134, in init_process
    self.load_wsgi()
  File "/usr/local/lib/python3.6/dist-packages/gunicorn/workers/base.py", line 146, in load_wsgi
    self.wsgi = self.app.wsgi()
  File "/usr/local/lib/python3.6/dist-packages/gunicorn/app/base.py", line 67, in wsgi
    self.callable = self.load()
  File "/usr/local/lib/python3.6/dist-packages/gunicorn/app/wsgiapp.py", line 58, in load
    return self.load_wsgiapp()
  File "/usr/local/lib/python3.6/dist-packages/gunicorn/app/wsgiapp.py", line 48, in load_wsgiapp
    return util.import_app(self.app_uri)
  File "/usr/local/lib/python3.6/dist-packages/gunicorn/util.py", line 359, in import_app
    mod = importlib.import_module(module)
  File "/usr/lib/python3.6/importlib/__init__.py", line 126, in import_module
    return _bootstrap._gcd_import(name[level:], package, level)
  File "<frozen importlib._bootstrap>", line 994, in _gcd_import
  File "<frozen importlib._bootstrap>", line 971, in _find_and_load
  File "<frozen importlib._bootstrap>", line 955, in _find_and_load_unlocked
  File "<frozen importlib._bootstrap>", line 665, in _load_unlocked
  File "<frozen importlib._bootstrap_external>", line 678, in exec_module
  File "<frozen importlib._bootstrap>", line 219, in _call_with_frames_removed
  File "/home/dive/main.py", line 2, in <module>
    from diveapi import app
  File "/home/dive/diveapi/__init__.py", line 12, in <module>
    fileConfig('/app/config/logger.cfg')
  File "/usr/lib/python3.6/logging/config.py", line 84, in fileConfig
    handlers = _install_handlers(cp, formatters)
  File "/usr/lib/python3.6/logging/config.py", line 148, in _install_handlers
    h = klass(*args)
  File "/usr/lib/python3.6/logging/__init__.py", line 1032, in __init__
    StreamHandler.__init__(self, self._open())
  File "/usr/lib/python3.6/logging/__init__.py", line 1061, in _open
    return open(self.baseFilename, self.mode, encoding=self.encoding)
PermissionError: [Errno 13] Permission denied: '/app/logs/diveapi.log'
[2022-08-23 13:12:14 +0000] [25] [INFO] Worker exiting (pid: 25)
[2022-08-23 13:12:14 +0000] [20] [WARNING] Worker with pid 24 was terminated due to signal 15
[2022-08-23 13:12:14 +0000] [20] [WARNING] Worker with pid 25 was terminated due to signal 15
[2022-08-23 13:12:14 +0000] [27] [ERROR] Exception in worker process
Traceback (most recent call last):
  File "/usr/local/lib/python3.6/dist-packages/gunicorn/arbiter.py", line 589, in spawn_worker
    worker.init_process()
  File "/usr/local/lib/python3.6/dist-packages/gunicorn/workers/base.py", line 134, in init_process
    self.load_wsgi()
  File "/usr/local/lib/python3.6/dist-packages/gunicorn/workers/base.py", line 146, in load_wsgi
    self.wsgi = self.app.wsgi()
  File "/usr/local/lib/python3.6/dist-packages/gunicorn/app/base.py", line 67, in wsgi
    self.callable = self.load()
  File "/usr/local/lib/python3.6/dist-packages/gunicorn/app/wsgiapp.py", line 58, in load
    return self.load_wsgiapp()
  File "/usr/local/lib/python3.6/dist-packages/gunicorn/app/wsgiapp.py", line 48, in load_wsgiapp
    return util.import_app(self.app_uri)
  File "/usr/local/lib/python3.6/dist-packages/gunicorn/util.py", line 359, in import_app
    mod = importlib.import_module(module)
  File "/usr/lib/python3.6/importlib/__init__.py", line 126, in import_module
    return _bootstrap._gcd_import(name[level:], package, level)
  File "<frozen importlib._bootstrap>", line 994, in _gcd_import
  File "<frozen importlib._bootstrap>", line 971, in _find_and_load
  File "<frozen importlib._bootstrap>", line 955, in _find_and_load_unlocked
  File "<frozen importlib._bootstrap>", line 665, in _load_unlocked
  File "<frozen importlib._bootstrap_external>", line 678, in exec_module
  File "<frozen importlib._bootstrap>", line 219, in _call_with_frames_removed
  File "/home/dive/main.py", line 2, in <module>
    from diveapi import app
  File "/home/dive/diveapi/__init__.py", line 12, in <module>
    fileConfig('/app/config/logger.cfg')
  File "/usr/lib/python3.6/logging/config.py", line 84, in fileConfig
    handlers = _install_handlers(cp, formatters)
  File "/usr/lib/python3.6/logging/config.py", line 148, in _install_handlers
    h = klass(*args)
  File "/usr/lib/python3.6/logging/__init__.py", line 1032, in __init__
    StreamHandler.__init__(self, self._open())
  File "/usr/lib/python3.6/logging/__init__.py", line 1061, in _open
    return open(self.baseFilename, self.mode, encoding=self.encoding)
PermissionError: [Errno 13] Permission denied: '/app/logs/diveapi.log'
[2022-08-23 13:12:14 +0000] [27] [INFO] Worker exiting (pid: 27)
Traceback (most recent call last):
  File "/usr/local/lib/python3.6/dist-packages/gunicorn/arbiter.py", line 209, in run
    self.sleep()
  File "/usr/local/lib/python3.6/dist-packages/gunicorn/arbiter.py", line 357, in sleep
    ready = select.select([self.PIPE[0]], [], [], 1.0)
  File "/usr/local/lib/python3.6/dist-packages/gunicorn/arbiter.py", line 242, in handle_chld
    self.reap_workers()
  File "/usr/local/lib/python3.6/dist-packages/gunicorn/arbiter.py", line 525, in reap_workers
    raise HaltServer(reason, self.WORKER_BOOT_ERROR)
gunicorn.errors.HaltServer: <HaltServer 'Worker failed to boot.' 3>

During handling of the above exception, another exception occurred:

Traceback (most recent call last):
  File "/usr/local/bin/gunicorn", line 11, in <module>
    sys.exit(run())
  File "/usr/local/lib/python3.6/dist-packages/gunicorn/app/wsgiapp.py", line 67, in run
    WSGIApplication("%(prog)s [OPTIONS] [APP_MODULE]").run()
  File "/usr/local/lib/python3.6/dist-packages/gunicorn/app/base.py", line 231, in run
    super().run()
  File "/usr/local/lib/python3.6/dist-packages/gunicorn/app/base.py", line 72, in run
    Arbiter(self).run()
  File "/usr/local/lib/python3.6/dist-packages/gunicorn/arbiter.py", line 229, in run
    self.halt(reason=inst.reason, exit_status=inst.exit_status)
  File "/usr/local/lib/python3.6/dist-packages/gunicorn/arbiter.py", line 342, in halt
    self.stop()
  File "/usr/local/lib/python3.6/dist-packages/gunicorn/arbiter.py", line 393, in stop
    time.sleep(0.1)
  File "/usr/local/lib/python3.6/dist-packages/gunicorn/arbiter.py", line 242, in handle_chld
    self.reap_workers()
  File "/usr/local/lib/python3.6/dist-packages/gunicorn/arbiter.py", line 525, in reap_workers
    raise HaltServer(reason, self.WORKER_BOOT_ERROR)
gunicorn.errors.HaltServer: <HaltServer 'Worker failed to boot.' 3>
